<?xml version="1.0" ?>
<!-- =================================================================================== -->
<!-- |    This document was autogenerated by xacro from               /thormang3.xacro | -->
<!-- |    EDITING THIS FILE BY HAND IS NOT RECOMMENDED                                 | -->
<!-- =================================================================================== -->
<!-- Revolute-Revolute Manipulator -->
<robot name="thormang" xmlns:xacro="http://www.ros.org/wiki/xacro">
    
    <material name="black">
        <color rgba="0.0 0.0 0.0 1.0"/>
    </material>
    <material name="blue">
        <color rgba="0.0 0.0 0.8 1.0"/>
    </material>
    <material name="green">
        <color rgba="0.0 0.8 0.0 1.0"/>
    </material>
    <material name="grey">
        <color rgba="0.2 0.2 0.2 1.0"/>
    </material>
    <material name="orange">
        <color rgba="1.0 0.423529411765 0.0392156862745 1.0"/>
    </material>
    <material name="brown">
        <color rgba="0.870588235294 0.811764705882 0.764705882353 1.0"/>
    </material>
    <material name="red">
        <color rgba="0.8 0.0 0.0 1.0"/>
    </material>
    <material name="white">
        <color rgba="1.0 1.0 1.0 1.0"/>
    </material>
    
    <link name="world">
    </link>
    
    <joint name="world_fixed" type="fixed">
        <origin xyz="0 0 0" rpy="0 0 0"/>
        <parent link="world"/>
        <child link="base"/>
    </joint>
    
    <joint name="base_fixed" type="fixed">
        <origin xyz="0 0 0.8" rpy="0 0 0"/>
        <parent link="base"/>
        <child link="pelvis_link"/>
    </joint>
    
    <link name="pelvis_link">
        <collision>
            <origin rpy="0 0 0" xyz="-0.01 0 0.07"/>
            <geometry>
                <box size="0.2 0.22 0.17"/>
            </geometry>
        </collision>
        <visual>
            <origin rpy="0 0 0" xyz="0 0 0"/>
            <geometry>
                <mesh filename="package://thormang3_description/meshes/robotis_pelvis_link.stl" scale="0.001 0.001 0.001"/>
            </geometry>
            <material name="grey"/>
        </visual>
        <inertial>
            <origin rpy="0 0 0" xyz="-0.011 0.000 0.058"/>
            <mass value="6.869"/>
            <inertia ixx="0.03603" ixy="0.0" ixz="0.00016" iyy="0.02210" iyz="0.0" izz="0.03830" />
        </inertial>
    </link>
    
    <joint name="torso_y" type="revolute">
        <parent link="pelvis_link"/>
        <child link="chest_link"/>
        <origin rpy="0 0 0" xyz="0 0 0.1705"/>
        <axis xyz="0 0 1"/>
        <limit effort="1000" lower="-1.8849555924" upper="1.8849555924" velocity="6.5"/>
        <dynamics damping="0.1" friction="0.0"/>
    </joint>
    
    <transmission name="torso_y_tran">
        <type>transmission_interface/SimpleTransmission</type>
        <joint name="torso_y">
            <hardwareInterface>EffortJointInterface</hardwareInterface>
        </joint>
        <actuator name="torso_y_motor">
            <hardwareInterface>EffortJointInterface</hardwareInterface>
            <mechanicalReduction>1</mechanicalReduction>
        </actuator>
    </transmission>
    
    <link name="chest_link">
        <collision>
            <origin rpy="0 0 0" xyz="-0.01 0 0.11"/>
            <geometry>
                <box size="0.2 0.25 0.23"/>
            </geometry>
        </collision>
        <visual>
            <origin rpy="0 0 0" xyz="0.0 0 0.0"/>
            <geometry>
                <mesh filename="package://sam_description/meshes/robotis_chest_link.stl" scale="0.001 0.001 0.001"/>
            </geometry>
            <material name="grey"/>
        </visual>
        <inertial>
            <origin rpy="0 0 0" xyz="-0.007 0.000 0.109"/>
            <mass value="5.383"/>
            <inertia ixx="0.04710" ixy="0.0" ixz="0.04710" iyy="0.02554" iyz="0.0" izz="0.03094"/>
        </inertial>
    </link>    
    
    <joint name="l_arm_sh_p1" type="revolute">
        <axis xyz="0 1 0"/>
        <origin rpy="0 0 0" xyz="0.0 0.152 0.16"/>
        <parent link="chest_link"/>
        <child link="l_arm_sh_p1_link"/>
        <limit effort="1000" lower="-2.0" upper="1.5707" velocity="6.5"/>
        <dynamics damping="0.1" friction="0.0"/>
    </joint>
    
    <transmission name="l_arm_sh_p1_tran">
        <type>transmission_interface/SimpleTransmission</type>
        <joint name="l_arm_sh_p1">
            <hardwareInterface>EffortJointInterface</hardwareInterface>
        </joint>
        <actuator name="l_arm_sh_p1_motor">
            <hardwareInterface>EffortJointInterface</hardwareInterface>
            <mechanicalReduction>1</mechanicalReduction>
        </actuator>
    </transmission>
    
    <link name="l_arm_sh_p1_link">
        <collision>
            <origin rpy="0 0 0" xyz="0 0.03 -0.01"/>
            <geometry>
                <box size="0.15 0.1 0.09"/>
            </geometry>
        </collision>
        <visual>
            <origin rpy="0 0 0" xyz="0 0 0"/>
            <geometry>
                <mesh filename="package://thormang3_description/meshes/robotis_l_arm_sh_p1_link.stl" scale="0.001 0.001 0.001"/>
            </geometry>
            <material name="grey"/>
        </visual>
        <inertial>
            <origin rpy="0 0 0" xyz="-0.003 0.020 -0.005"/>
            <mass value="0.194"/>
            <inertia ixx="1.0" ixy="0.0" ixz="0.0" iyy="1.0" iyz="0.0" izz="1.0"/>
        </inertial>
    </link>
    
    <joint name="l_arm_sh_r" type="revolute">
        <axis xyz="-1 0 0"/>
        <origin rpy="0 0 0" xyz="0.057 0.060 -0.039"/>
        <parent link="l_arm_sh_p1_link"/>
        <child link="l_arm_sh_r_link"/>
        <limit effort="1000" lower="0.6" upper="2.0" velocity="6.5"/>
        <dynamics damping="0.1" friction="0.0"/>
    </joint>
    
    <transmission name="l_arm_sh_r_tran">
        <type>transmission_interface/SimpleTransmission</type>
        <joint name="l_arm_sh_r">
            <hardwareInterface>EffortJointInterface</hardwareInterface>
        </joint>
        <actuator name="l_arm_sh_r_motor">
            <hardwareInterface>EffortJointInterface</hardwareInterface>
            <mechanicalReduction>1</mechanicalReduction>
        </actuator>
    </transmission>
    
    <link name="l_arm_sh_r_link">
        <collision>
            <origin rpy="0 0 0" xyz="-0.057 0 0"/>
            <geometry>
                <box size="0.14 0.07 0.07"/>
            </geometry>
        </collision>
        <visual>
            <origin rpy="0 0 0" xyz="0 0 0"/>
            <geometry>
                <mesh filename="package://thormang3_description/meshes/robotis_l_arm_sh_r_link.stl" scale="0.001 0.001 0.001"/>
            </geometry>
            <material name="grey"/>
        </visual>
        <inertial>
            <origin rpy="0 0 0" xyz="-0.060 0.002 0.000"/>
            <mass value="0.875"/>
            <inertia ixx="1.0" ixy="0.0" ixz="0.0" iyy="1.0" iyz="0.0" izz="1.0"/>
        </inertial>
    </link>
    
    <joint name="l_arm_sh_p2" type="revolute">
        <axis xyz="0 1 0"/>
        <origin rpy="0 0 0" xyz="-0.057 0.033 0.0"/>
        <parent link="l_arm_sh_r_link"/>
        <child link="l_arm_sh_p2_link"/>
        <limit effort="1000" lower="-1.2" upper="2.4" velocity="6.5"/>
        <dynamics damping="0.1" friction="0.0"/>
    </joint>
    
    <transmission name="l_arm_sh_p2_tran">
        <type>transmission_interface/SimpleTransmission</type>
        <joint name="l_arm_sh_p2">
            <hardwareInterface>EffortJointInterface</hardwareInterface>
        </joint>
        <actuator name="l_arm_sh_p2_motor">
            <hardwareInterface>EffortJointInterface</hardwareInterface>
            <mechanicalReduction>1</mechanicalReduction>
        </actuator>
    </transmission>
    
    <link name="l_arm_sh_p2_link">
        <collision>
            <origin rpy="0 0 0" xyz="0.01 0.11 0"/>
            <geometry>
                <box size="0.1 0.24 0.13"/>
            </geometry>
        </collision>
        <visual>
            <origin rpy="0 0 0" xyz="0 0 0"/>
            <geometry>
                <mesh filename="package://thormang3_description/meshes/robotis_l_arm_sh_p2_link.stl" scale="0.001 0.001 0.001"/>
            </geometry>
            <material name="grey"/>
        </visual>
        <inertial>
            <origin rpy="0 0 0" xyz="0.000 0.073 0.000"/>
            <mass value="1.122"/>
            <inertia ixx="1.0" ixy="0.0" ixz="0.0" iyy="1.0" iyz="0.0" izz="1.0"/>
        </inertial>
    </link>
    
    <joint name="l_arm_el_y" type="revolute">
        <axis xyz="0 0 -1"/>
        <origin rpy="0 0 0" xyz="0.030 0.187 0.057"/>
        <parent link="l_arm_sh_p2_link"/>
        <child link="l_arm_el_y_link"/>
        <limit effort="1000" lower="-1.2" upper="1.2566370616" velocity="6.5"/>
        <dynamics damping="0.1" friction="0.0"/>
    </joint>
    
    <transmission name="l_arm_el_y_tran">
        <type>transmission_interface/SimpleTransmission</type>
        <joint name="l_arm_el_y">
            <hardwareInterface>EffortJointInterface</hardwareInterface>
        </joint>
        <actuator name="l_arm_el_y_motor">
            <hardwareInterface>EffortJointInterface</hardwareInterface>
            <mechanicalReduction>1</mechanicalReduction>
        </actuator>
    </transmission>
    
    <link name="l_arm_el_y_link">
        <collision>
            <origin rpy="0 0 0" xyz="0.08 0.01 -0.057"/>
            <geometry>
                <box size="0.17 0.1 0.08"/>
            </geometry>
        </collision>
        <visual>
            <origin rpy="0 0 0" xyz="0 0 0"/>
            <geometry>
                <mesh filename="package://thormang3_description/meshes/robotis_l_arm_el_y_link.stl" scale="0.001 0.001 0.001"/>
            </geometry>
            <material name="grey"/>
        </visual>
        <inertial>
            <origin rpy="0 0 0" xyz="0.042 0.012 -0.058"/>
            <mass value="1.357"/>
            <inertia ixx="1.0" ixy="0.0" ixz="0.0" iyy="1.0" iyz="0.0" izz="1.0"/>
        </inertial>
    </link>
    
    <joint name="l_arm_wr_r" type="revolute">
        <axis xyz="1 0 0"/>
        <origin rpy="0 0 0" xyz="0.171 0.030 -0.057"/>
        <parent link="l_arm_el_y_link"/>
        <child link="l_arm_wr_r_link"/>
        <limit effort="1000" lower="0.0" upper="2.0" velocity="6.5"/>
        <dynamics damping="0.1" friction="0.0"/>
    </joint>
    
    <transmission name="l_arm_wr_r_tran">
        <type>transmission_interface/SimpleTransmission</type>
        <joint name="l_arm_wr_r">
            <hardwareInterface>EffortJointInterface</hardwareInterface>
        </joint>
        <actuator name="l_arm_wr_r_motor">
            <hardwareInterface>EffortJointInterface</hardwareInterface>
            <mechanicalReduction>1</mechanicalReduction>
        </actuator>
    </transmission>
    
    <link name="l_arm_wr_r_link">
        <collision>
            <origin rpy="0 0 0" xyz="0.02 0 0"/>
            <geometry>
                <box size="0.05 0.05 0.11"/>
            </geometry>
        </collision>
        <visual>
            <origin rpy="0 0 0" xyz="0 0 0"/>
            <geometry>
                <mesh filename="package://thormang3_description/meshes/robotis_l_arm_wr_r_link.stl" scale="0.001 0.001 0.001"/>
            </geometry>
            <material name="grey"/>
        </visual>
        <inertial>
            <origin rpy="0 0 0" xyz="0.010 0.000 0.002"/>
            <mass value="0.087"/>
            <inertia ixx="0.00012" ixy="0.0" ixz="0.0" iyy="0.00011" iyz="0.0" izz="0.00003" />
        </inertial>
    </link>
    
    <joint name="l_arm_wr_y" type="revolute">
        <axis xyz="0 0 -1"/>
        <origin rpy="0 0 0" xyz="0.039 0.0 0.045"/>
        <parent link="l_arm_wr_r_link"/>
        <child link="l_arm_wr_y_link"/>
        <limit effort="1000" lower="-1.4137166943" upper="1.4137166943" velocity="6.5"/>
        <dynamics damping="0.1" friction="0.0"/>
    </joint>
    
    <transmission name="l_arm_wr_y_tran">
        <type>transmission_interface/SimpleTransmission</type>
        <joint name="l_arm_wr_y">
            <hardwareInterface>EffortJointInterface</hardwareInterface>
        </joint>
        <actuator name="l_arm_wr_y_motor">
            <hardwareInterface>EffortJointInterface</hardwareInterface>
            <mechanicalReduction>1</mechanicalReduction>
        </actuator>
    </transmission>
    
    <link name="l_arm_wr_y_link">
        <collision>
            <origin rpy="0 0 0" xyz="0.03 0 -0.045"/>
            <geometry>
                <box size="0.09 0.1 0.09"/>
            </geometry>
        </collision>
        <visual>
            <origin rpy="0 0 0" xyz="0 0 0"/>
            <geometry>
                <mesh filename="package://thormang3_description/meshes/robotis_l_arm_wr_y_link.stl" scale="0.001 0.001 0.001"/>
            </geometry>
            <material name="grey"/>
        </visual>
        <inertial>
            <origin rpy="0 0 0" xyz="0.023 0.001 -0.046"/>
            <mass value="0.768"/>
            <inertia ixx="0.00059" ixy="-0.00002" ixz="-0.00002" iyy="0.00078" iyz="0.0" izz="0.00078" />
        </inertial>
    </link>
    
    <joint name="r_arm_sh_p1" type="revolute">
        <axis xyz="0 -1 0"/>
        <origin rpy="0 0 0" xyz="0.0 -0.152 0.16"/>
        <parent link="chest_link"/>
        <child link="r_arm_sh_p1_link"/>
        <limit effort="1000" lower="-1.5707" upper="2.0" velocity="6.5"/>
        <dynamics damping="0.1" friction="0.0"/>
    </joint>
    
    <transmission name="r_arm_sh_p1_tran">
        <type>transmission_interface/SimpleTransmission</type>
        <joint name="r_arm_sh_p1">
            <hardwareInterface>EffortJointInterface</hardwareInterface>
        </joint>
        <actuator name="r_arm_sh_p1_motor">
            <hardwareInterface>EffortJointInterface</hardwareInterface>
            <mechanicalReduction>1</mechanicalReduction>
        </actuator>
    </transmission>
    
    <link name="r_arm_sh_p1_link">
        <collision>
            <origin rpy="0 0 0" xyz="0 -0.03 -0.01"/>
            <geometry>
                <box size="0.15 0.1 0.09"/>
            </geometry>
        </collision>
        <visual>
            <origin rpy="0 0 0" xyz="0 0 0"/>
            <geometry>
                <mesh filename="package://thormang3_description/meshes/robotis_r_arm_sh_p1_link.stl" scale="0.001 0.001 0.001"/>
            </geometry>
            <material name="grey"/>
        </visual>
        <inertial>
            <origin rpy="0 0 0" xyz="-0.003 -0.020 -0.005"/>
            <mass value="0.194"/>
            <inertia ixx="0.00018" ixy="0.0" ixz="0.0" iyy="0.00058" iyz="-0.00004" izz="0.00057" />
        </inertial>
    </link>
    
    <joint name="r_arm_sh_r" type="revolute">
        <axis xyz="-1 0 0"/>
        <origin rpy="0 0 0" xyz="0.057 -0.060 -0.039"/>
        <parent link="r_arm_sh_p1_link"/>
        <child link="r_arm_sh_r_link"/>
        <limit effort="1000" lower="-2.0" upper="-0.6" velocity="6.5"/>
        <dynamics damping="0.1" friction="0.0"/>
    </joint>
    
    <transmission name="r_arm_sh_r_tran">
        <type>transmission_interface/SimpleTransmission</type>
        <joint name="r_arm_sh_r">
            <hardwareInterface>EffortJointInterface</hardwareInterface>
        </joint>
        <actuator name="r_arm_sh_r_motor">
            <hardwareInterface>EffortJointInterface</hardwareInterface>
            <mechanicalReduction>1</mechanicalReduction>
        </actuator>
    </transmission>
    
    <link name="r_arm_sh_r_link">
        <collision>
            <origin rpy="0 0 0" xyz="-0.057 0 0"/>
            <geometry>
                <box size="0.14 0.07 0.07"/>
            </geometry>
        </collision>
        <visual>
            <origin rpy="0 0 0" xyz="0 0 0"/>
            <geometry>
                <mesh filename="package://thormang3_description/meshes/robotis_r_arm_sh_r_link.stl" scale="0.001 0.001 0.001"/>
            </geometry>
            <material name="grey"/>
        </visual>
        <inertial>
            <origin rpy="0 0 0" xyz="-0.060 -0.002 0.000"/>
            <mass value="0.875"/>
            <inertia ixx="0.00043" ixy="0.0" ixz="0.0" iyy="0.00112" iyz="0.0" izz="0.00113" />
        </inertial>
    </link>
    
    <joint name="r_arm_sh_p2" type="revolute">
        <axis xyz="0 -1 0"/>
        <origin rpy="0 0 0" xyz="-0.057 -0.033 0.0"/>
        <parent link="r_arm_sh_r_link"/>
        <child link="r_arm_sh_p2_link"/>
        <limit effort="1000" lower="-2.8" upper="0.8" velocity="6.5"/>
        <dynamics damping="0.1" friction="0.0"/>
    </joint>
    
    <transmission name="r_arm_sh_p2_tran">
        <type>transmission_interface/SimpleTransmission</type>
        <joint name="r_arm_sh_p2">
            <hardwareInterface>EffortJointInterface</hardwareInterface>
        </joint>
        <actuator name="r_arm_sh_p2_motor">
            <hardwareInterface>EffortJointInterface</hardwareInterface>
            <mechanicalReduction>1</mechanicalReduction>
        </actuator>
    </transmission>
    
    <link name="r_arm_sh_p2_link">
        <collision>
            <origin rpy="0 0 0" xyz="0.01 -0.11 0"/>
            <geometry>
                <box size="0.1 0.24 0.13"/>
            </geometry>
        </collision>
        <visual>
            <origin rpy="0 0 0" xyz="0 0 0"/>
            <geometry>
                <mesh filename="package://thormang3_description/meshes/robotis_r_arm_sh_p2_link.stl" scale="0.001 0.001 0.001"/>
            </geometry>
            <material name="grey"/>
        </visual>
        <inertial>
            <origin rpy="0 0 0" xyz="0.000 -0.073 0.000"/>
            <mass value="1.122"/>
            <inertia ixx="0.00277" ixy="0.00002" ixz="-0.00001" iyy="0.00090" iyz="0.00004" izz="0.00255" />
        </inertial>
    </link>
    
    <joint name="r_arm_el_y" type="revolute">
        <axis xyz="0 0 -1"/>
        <origin rpy="0 0 0" xyz="0.030 -0.187 0.057"/>
        <parent link="r_arm_sh_p2_link"/>
        <child link="r_arm_el_y_link"/>
        <limit effort="1000" lower="-1.2566370616" upper="1.2" velocity="6.5"/>
        <dynamics damping="0.1" friction="0.0"/>
    </joint>
    
    <transmission name="r_arm_el_y_tran">
        <type>transmission_interface/SimpleTransmission</type>
        <joint name="r_arm_el_y">
            <hardwareInterface>EffortJointInterface</hardwareInterface>
        </joint>
        <actuator name="r_arm_el_y_motor">
            <hardwareInterface>EffortJointInterface</hardwareInterface>
            <mechanicalReduction>1</mechanicalReduction>
        </actuator>
    </transmission>
    
    <link name="r_arm_el_y_link">
        <collision>
            <origin rpy="0 0 0" xyz="0.08 -0.01 -0.057"/>
            <geometry>
                <box size="0.17 0.1 0.08"/>
            </geometry>
        </collision>
        <visual>
            <origin rpy="0 0 0" xyz="0 0 0"/>
            <geometry>
                <mesh filename="package://thormang3_description/meshes/robotis_r_arm_el_y_link.stl" scale="0.001 0.001 0.001"/>
            </geometry>
            <material name="grey"/>
        </visual>
        <inertial>
            <origin rpy="0 0 0" xyz="0.042 -0.012 -0.058"/>
            <mass value="1.357"/>
            <inertia ixx="0.00152" ixy="0.00100" ixz="-0.00006" iyy="0.00560" iyz="0.00002" izz="0.00528" />
        </inertial>
    </link>
    
    <joint name="r_arm_wr_r" type="revolute">
        <axis xyz="1 0 0"/>
        <origin rpy="0 0 0" xyz="0.171 -0.030 -0.057"/>
        <parent link="r_arm_el_y_link"/>
        <child link="r_arm_wr_r_link"/>
        <limit effort="1000" lower="-2.0" upper="0.0" velocity="6.5"/>
        <dynamics damping="0.1" friction="0.0"/>
    </joint>
    
    <transmission name="r_arm_wr_r_tran">
        <type>transmission_interface/SimpleTransmission</type>
        <joint name="r_arm_wr_r">
            <hardwareInterface>EffortJointInterface</hardwareInterface>
        </joint>
        <actuator name="r_arm_wr_r_motor">
            <hardwareInterface>EffortJointInterface</hardwareInterface>
            <mechanicalReduction>1</mechanicalReduction>
        </actuator>
    </transmission>
    
    <link name="r_arm_wr_r_link">
        <collision>
            <origin rpy="0 0 0" xyz="0.02 0 0"/>
            <geometry>
                <box size="0.05 0.05 0.11"/>
            </geometry>
        </collision>
        <visual>
            <origin rpy="0 0 0" xyz="0 0 0"/>
            <geometry>
                <mesh filename="package://thormang3_description/meshes/robotis_r_arm_wr_r_link.stl" scale="0.001 0.001 0.001"/>
            </geometry>
            <material name="grey"/>
        </visual>
        <inertial>
            <origin rpy="0 0 0" xyz="0.010 0.000 -0.002"/>
            <mass value="0.087"/>
            <inertia ixx="0.00012" ixy="0.0" ixz="0.0" iyy="0.00011" iyz="0.0" izz="0.00003" />
        </inertial>
    </link>
    
    <joint name="r_arm_wr_y" type="revolute">
        <axis xyz="0 0 -1"/>
        <origin rpy="0 0 0" xyz="0.039 0.0 0.045"/>
        <parent link="r_arm_wr_r_link"/>
        <child link="r_arm_wr_y_link"/>
        <limit effort="1000" lower="-1.4137166943" upper="1.4137166943" velocity="6.5"/>
        <dynamics damping="0.1" friction="0.0"/>
    </joint>
    
    <transmission name="r_arm_wr_y_tran">
        <type>transmission_interface/SimpleTransmission</type>
        <joint name="r_arm_wr_y">
            <hardwareInterface>EffortJointInterface</hardwareInterface>
        </joint>
        <actuator name="r_arm_wr_y_motor">
            <hardwareInterface>EffortJointInterface</hardwareInterface>
            <mechanicalReduction>1</mechanicalReduction>
        </actuator>
    </transmission>
    
    <link name="r_arm_wr_y_link">
        <collision>
            <origin rpy="0 0 0" xyz="0.03 0 -0.045"/>
            <geometry>
                <box size="0.09 0.1 0.09"/>
            </geometry>
        </collision>
        <visual>
            <origin rpy="0 0 0" xyz="0 0 0"/>
            <geometry>
                <mesh filename="package://thormang3_description/meshes/robotis_r_arm_wr_y_link.stl" scale="0.001 0.001 0.001"/>
            </geometry>
            <material name="grey"/>
        </visual>
        <inertial>
            <origin rpy="0 0 0" xyz="0.023 -0.001 -0.046"/>
            <mass value="0.768"/>
            <inertia ixx="1.0" ixy="0.0" ixz="0.0" iyy="1.0" iyz="0.0" izz="1.0"/>
        </inertial>
    </link>
    
    <joint name="l_leg_hip_y" type="revolute">
        <axis xyz="0 0 -1" />   
        <origin xyz="0.0 0.093 -0.018" rpy="0 0 0"/>
        <parent link="pelvis_link"/>
        <child link="l_leg_hip_y_link"/>
        <limit velocity="6.5" effort="1000" lower="${-pi*0.45}" upper="${pi*0.45}" />
    </joint>
    
    <link name="l_leg_hip_y_link">
        <collision>
            <origin rpy="0 0 0" xyz="-0.01 0 -0.05"/>
            <geometry>
                <box size="0.17 0.07 0.1"/>
            </geometry>
        </collision>
        <visual>
            <origin rpy="0 0 0" xyz="0 0 0"/>
            <geometry>
                <mesh filename="package://thormang3_description/meshes/robotis_l_leg_hip_y_link.stl" scale="0.001 0.001 0.001"/>
            </geometry>
            <material name="grey"/>
        </visual>
        <inertial>
            <origin rpy="0 0 0" xyz="0.012 0.000 -0.025"/>
            <mass value="0.243"/>
            <inertia ixx="1.0" ixy="0.0" ixz="0.0" iyy="1.0" iyz="0.0" izz="1.0"/>
        </inertial>
    </link>
    
    <joint name="l_leg_hip_r" type="revolute">
        <axis xyz="-1 0 0"/>
        <origin rpy="0 0 0" xyz="0.057 0.0 -0.075"/>
        <parent link="l_leg_hip_y_link"/>
        <child link="l_leg_hip_r_link"/>
        <limit effort="1000" lower="-0.0" upper="0.0" velocity="6.5"/>
        <dynamics damping="0.1" friction="0.0"/>
    </joint>
    
    <transmission name="l_leg_hip_r_tran">
        <type>transmission_interface/SimpleTransmission</type>
        <joint name="l_leg_hip_r">
            <hardwareInterface>EffortJointInterface</hardwareInterface>
        </joint>
        <actuator name="l_leg_hip_r_motor">
            <hardwareInterface>EffortJointInterface</hardwareInterface>
            <mechanicalReduction>1</mechanicalReduction>
        </actuator>
    </transmission>
    
    <link name="l_leg_hip_r_link">
        <visual>
            <origin rpy="0 0 0" xyz="0 0 0"/>
            <geometry>
                <mesh filename="package://thormang3_description/meshes/robotis_l_leg_hip_r_link.stl" scale="0.001 0.001 0.001"/>
            </geometry>
            <material name="grey"/>
        </visual>
        <inertial>
            <origin rpy="0 0 0" xyz="-0.068 0.000 0.000"/>
            <mass value="1.045"/>
            <inertia ixx="1.0" ixy="0.0" ixz="0.0" iyy="1.0" iyz="0.0" izz="1.0"/>
        </inertial>
    </link>
    
    <joint name="l_leg_hip_p" type="revolute">
        <axis xyz="0 -1 0"/>
        <origin rpy="0 0 0" xyz="-0.057 0.033 0.0"/>
        <parent link="l_leg_hip_r_link"/>
        <child link="l_leg_hip_p_link"/>
        <limit effort="1000" lower="-0.87" upper="0.87" velocity="6.5"/>
        <dynamics damping="0.1" friction="0.0"/>
    </joint>
    
    <transmission name="l_leg_hip_p_tran">
        <type>transmission_interface/SimpleTransmission</type>
        <joint name="l_leg_hip_p">
            <hardwareInterface>EffortJointInterface</hardwareInterface>
        </joint>
        <actuator name="l_leg_hip_p_motor">
            <hardwareInterface>EffortJointInterface</hardwareInterface>
            <mechanicalReduction>1</mechanicalReduction>
        </actuator>
    </transmission>
    
    <link name="l_leg_hip_p_link">
        <collision>
            <origin rpy="0 0 0" xyz="0 -0.005 -0.145"/>
            <geometry>
                <box size="0.11 0.16 0.33"/>
            </geometry>
        </collision>
        <visual>
            <origin rpy="0 0 0" xyz="0 0 0"/>
            <geometry>
                <mesh filename="package://thormang3_description/meshes/robotis_l_leg_hip_p_link.stl" scale="0.001 0.001 0.001"/>
            </geometry>
            <material name="grey"/>
        </visual>
        <inertial>
            <origin rpy="0 0 0" xyz="0.022 -0.007 -0.168"/>
            <mass value="3.095"/>
            <inertia ixx="1.0" ixy="0.0" ixz="0.0" iyy="1.0" iyz="0.0" izz="1.0"/>
        </inertial>
    </link>
    
    
    <joint name="l_leg_kn_p" type="revolute">
        <axis xyz="0 1 0" />		
        <origin xyz="0.0 0.06 -0.3" rpy="0 0 0"/>
        <parent link="l_leg_hip_p_link"/>
        <child link="l_leg_kn_p_link"/>
        <limit velocity="6.5" effort="1000" lower="${-pi*0.1}" upper="${pi*0.7}" />
        <dynamics damping="0.1" friction="0.0" />
    </joint> 
    
    
    <link name="l_leg_kn_p_link">
        <collision>
            <origin rpy="0 0 0" xyz="0.01 -0.065 -0.145"/>
            <geometry>
                <box size="0.11 0.16 0.33"/>
            </geometry>
        </collision>
        <visual>
            <origin rpy="0 0 0" xyz="0 0 0"/>
            <geometry>
                <mesh filename="package://thormang3_description/meshes/robotis_l_leg_kn_p_link.stl" scale="0.001 0.001 0.001"/>
            </geometry>
            <material name="grey"/>
        </visual>
        <inertial>
            <origin rpy="0 0 0" xyz="-0.002 -0.066 -0.183"/>
            <mass value="2.401"/>
            <inertia ixx="1.0" ixy="0.0" ixz="0.0" iyy="1.0" iyz="0.0" izz="1.0"/>
        </inertial>
    </link>
    
    
    <joint name="l_leg_an_p" type="revolute">
        <axis xyz="0 -1 0" />		
        <origin xyz="-0.0 -0.06 -0.3" rpy="0 0 0"/>
        <parent link="l_leg_kn_p_link"/>
        <child link="l_leg_an_p_link"/>
        <limit velocity="6.5" effort="1000" lower="${-pi*0.45}" upper="${pi*0.45}" />
        <dynamics damping="0.1" friction="0.0" />
    </joint> 
    
    
    
    <link name="l_leg_an_p_link">
        <visual>
            <origin rpy="0 0 0" xyz="0 0 0"/>
            <geometry>
                <mesh filename="package://thormang3_description/meshes/robotis_l_leg_an_p_link.stl" scale="0.001 0.001 0.001"/>
            </geometry>
            <material name="grey"/>
        </visual>
        <inertial>
            <origin rpy="0 0 0" xyz="-0.011 -0.033 0.000"/>
            <mass value="1.045"/>
            <inertia ixx="1.0" ixy="0.0" ixz="0.0" iyy="1.0" iyz="0.0" izz="1.0"/>
        </inertial>
    </link>
    
    <joint name="l_leg_an_r" type="revolute">
        <axis xyz="1 0 0" />		
        <origin xyz="0.057 -0.033 0.0" rpy="0 0 0"/>
        <parent link="l_leg_an_p_link"/>
        <child link="l_leg_an_r_link"/>
        <limit velocity="6.5" effort="1000" lower="${-pi*0.5}" upper="${pi*0.4}" />
        <dynamics damping="0.1" friction="0.0" />
    </joint> 
    
    
    <link name="l_leg_an_r_link">
        <collision>
            <origin rpy="0 0 0" xyz="-0.067 0 -0.02"/>
            <geometry>
                <box size="0.17 0.06 0.12"/>
            </geometry>
        </collision>
        <visual>
            <origin rpy="0 0 0" xyz="0 0 0"/>
            <geometry>
                <mesh filename="package://thormang3_description/meshes/robotis_l_leg_an_r_link.stl" scale="0.001 0.001 0.001"/>
            </geometry>
            <material name="grey"/>
        </visual>
        <inertial>
            <origin rpy="0 0 0" xyz="-0.070 0.000 -0.048"/>
            <mass value="0.223"/>
            <inertia ixx="1.0" ixy="0.0" ixz="0.0" iyy="1.0" iyz="0.0" izz="1.0"/>
        </inertial>
    </link>
    
    <joint name="r_leg_hip_y" type="revolute">
        <axis xyz="0 0 -1" />		
        <origin xyz="0.0 -0.093 -0.018" rpy="0 0 0"/>
        <parent link="pelvis_link"/>
        <child link="r_leg_hip_y_link"/>
        <limit velocity="6.5" effort="1000" lower="${-pi*0.45}" upper="${pi*0.45}" />
        <dynamics damping="0.1" friction="0.0" />
    </joint> 
    
    <link name="r_leg_hip_y_link">
        <collision>
            <origin rpy="0 0 0" xyz="-0.01 0 -0.05"/>
            <geometry>
                <box size="0.17 0.07 0.1"/>
            </geometry>
        </collision>
        <visual>
            <origin rpy="0 0 0" xyz="0 0 0"/>
            <geometry>
                <mesh filename="package://thormang3_description/meshes/robotis_r_leg_hip_y_link.stl" scale="0.001 0.001 0.001"/>
            </geometry>
            <material name="grey"/>
        </visual>
        <inertial>
            <origin rpy="0 0 0" xyz="-0.012 0.000 -0.025"/>
            <mass value="0.243"/>
            <inertia ixx="1.0" ixy="0.0" ixz="0.0" iyy="1.0" iyz="0.0" izz="1.0"/>
        </inertial>
    </link>
    
    <joint name="r_leg_hip_r" type="revolute">
        <axis xyz="-1 0 0"/>
        <origin rpy="0 0 0" xyz="0.057 0.0 -0.075"/>
        <parent link="r_leg_hip_y_link"/>
        <child link="r_leg_hip_r_link"/>
        <limit effort="1000" lower="-0.9424777962" upper="0.6283185308" velocity="6.5"/>
        <dynamics damping="0.1" friction="0.0"/>
    </joint>
    
    <transmission name="r_leg_hip_r_tran">
        <type>transmission_interface/SimpleTransmission</type>
        <joint name="r_leg_hip_r">
            <hardwareInterface>EffortJointInterface</hardwareInterface>
        </joint>
        <actuator name="r_leg_hip_r_motor">
            <hardwareInterface>EffortJointInterface</hardwareInterface>
            <mechanicalReduction>1</mechanicalReduction>
        </actuator>
    </transmission>
    
    <link name="r_leg_hip_r_link">
        <visual>
            <origin rpy="0 0 0" xyz="0 0 0"/>
            <geometry>
                <mesh filename="package://thormang3_description/meshes/robotis_r_leg_hip_r_link.stl" scale="0.001 0.001 0.001"/>
            </geometry>
            <material name="grey"/>
        </visual>
        <inertial>
            <origin rpy="0 0 0" xyz="-0.068 0.000 0.000"/>
            <mass value="1.045"/>
            <inertia ixx="1.0" ixy="0.0" ixz="0.0" iyy="1.0" iyz="0.0" izz="1.0"/>
        </inertial>
    </link>
    
    <joint name="r_leg_hip_p" type="revolute">
        <axis xyz="0 -1 0"/>
        <origin rpy="0 0 0" xyz="-0.057 -0.033 0.0"/>
        <parent link="r_leg_hip_r_link"/>
        <child link="r_leg_hip_p_link"/>
        <limit effort="1000" lower="-0.87" upper="0.87" velocity="6.5"/>
        <dynamics damping="0.1" friction="0.0"/>
        <mimic joint="l_leg_hip_p" multiplier="-1.0" offset="0.0"/>
    </joint>
    
    <transmission name="r_leg_hip_p_tran">
        <type>transmission_interface/SimpleTransmission</type>
        <joint name="r_leg_hip_p">
            <hardwareInterface>EffortJointInterface</hardwareInterface>
        </joint>
        <actuator name="r_leg_hip_p_motor">
            <hardwareInterface>EffortJointInterface</hardwareInterface>
            <mechanicalReduction>1</mechanicalReduction>
        </actuator>
    </transmission>
    
    <link name="r_leg_hip_p_link">
        <collision>
            <origin rpy="0 0 0" xyz="0 0.005 -0.145"/>
            <geometry>
                <box size="0.11 0.16 0.33"/>
            </geometry>
        </collision>
        <visual>
            <origin rpy="0 0 0" xyz="0 0 0"/>
            <geometry>
                <mesh filename="package://thormang3_description/meshes/robotis_r_leg_hip_p_link.stl" scale="0.001 0.001 0.001"/>
            </geometry>
            <material name="grey"/>
        </visual>
        <inertial>
            <origin rpy="0 0 0" xyz="0.022 0.007 -0.168"/>
            <mass value="3.095"/>
            <inertia ixx="1.0" ixy="0.0" ixz="0.0" iyy="1.0" iyz="0.0" izz="1.0"/>
        </inertial>
    </link>
    
    
    <joint name="r_leg_kn_p" type="revolute">
        <axis xyz="0 -1 0" />		
        <origin xyz="0.0 -0.06 -0.3" rpy="0 0 0"/>
        <parent link="r_leg_hip_p_link"/>
        <child link="r_leg_kn_p_link"/>
        <limit velocity="6.5" effort="1000" lower="${-pi*0.7}" upper="${pi*0.1}" />
        <dynamics damping="0.1" friction="0.0" />
    </joint> 
    
    
    <link name="r_leg_kn_p_link">
        <collision>
            <origin rpy="0 0 0" xyz="0.01 0.065 -0.145"/>
            <geometry>
                <box size="0.11 0.16 0.33"/>
            </geometry>
        </collision>
        <visual>
            <origin rpy="0 0 0" xyz="0 0 0"/>
            <geometry>
                <mesh filename="package://thormang3_description/meshes/robotis_r_leg_kn_p_link.stl" scale="0.001 0.001 0.001"/>
            </geometry>
            <material name="grey"/>
        </visual>
        <inertial>
            <origin rpy="0 0 0" xyz="-0.002 0.066 -0.183"/>
            <mass value="2.401"/>
            <inertia ixx="1.0" ixy="0.0" ixz="0.0" iyy="1.0" iyz="0.0" izz="1.0"/>
        </inertial>
    </link>
    
    
    <joint name="r_leg_an_p" type="revolute">
        <axis xyz="0 1 0" />		
        <origin xyz="-0.0 0.06 -0.3" rpy="0 0 0"/>
        <parent link="r_leg_kn_p_link"/>
        <child link="r_leg_an_p_link"/>
        <limit velocity="6.5" effort="1000" lower="${-pi*0.45}" upper="${pi*0.45}" />
        <dynamics damping="0.1" friction="0.0" />
    </joint> 
    
        
    <link name="r_leg_an_p_link">
        <visual>
            <origin rpy="0 0 0" xyz="0 0 0"/>
            <geometry>
                <mesh filename="package://thormang3_description/meshes/robotis_r_leg_an_p_link.stl" scale="0.001 0.001 0.001"/>
            </geometry>
            <material name="grey"/>
        </visual>
        <inertial>
            <origin rpy="0 0 0" xyz="-0.011 0.033 0.000"/>
            <mass value="1.045"/>
            <inertia ixx="1.0" ixy="0.0" ixz="0.0" iyy="1.0" iyz="0.0" izz="1.0"/>
        </inertial>
    </link>
    
    
    <joint name="r_leg_an_r" type="revolute">
        <axis xyz="1 0 0" />		
        <origin xyz="0.057 0.033 0.0" rpy="0 0 0"/>
        <parent link="r_leg_an_p_link"/>
        <child link="r_leg_an_r_link"/>
        <limit velocity="6.5" effort="1000" lower="${-pi*0.45}" upper="${pi*0.45}" />
        <dynamics damping="0.1" friction="0.0" />
    </joint> 
    
    
    <link name="r_leg_an_r_link">
        <collision>
            <origin rpy="0 0 0" xyz="-0.067 0 -0.02"/>
            <geometry>
                <box size="0.17 0.06 0.12"/>
            </geometry>
        </collision>
        <visual>
            <origin rpy="0 0 0" xyz="0 0 0"/>
            <geometry>
                <mesh filename="package://thormang3_description/meshes/robotis_r_leg_an_r_link.stl" scale="0.001 0.001 0.001"/>
            </geometry>
            <material name="grey"/>
        </visual>
        <inertial>
            <origin rpy="0 0 0" xyz="-0.070 0.000 -0.048"/>
            <mass value="0.223"/>
            <inertia ixx="1.0" ixy="0.0" ixz="0.0" iyy="1.0" iyz="0.0" izz="1.0"/>
        </inertial>
    </link>
    
    <joint name="head_y" type="revolute">
        <axis xyz="0 0 1" />    
        <origin xyz="0.0 0.0 0.229" rpy="0 0 0"/>
        <parent link="chest_link"/>
        <child link="head_y_link"/>
        <limit effort="1000" lower="-1.570796327" upper="1.570796327" velocity="6.5"/>
        <dynamics damping="0.1" friction="0.0"/>
    </joint>
    
    <transmission name="head_y_tran">
        <type>transmission_interface/SimpleTransmission</type>
        <joint name="head_y">
            <hardwareInterface>EffortJointInterface</hardwareInterface>
        </joint>
        <actuator name="head_y_motor">
            <hardwareInterface>EffortJointInterface</hardwareInterface>
            <mechanicalReduction>1</mechanicalReduction>
        </actuator>
    </transmission>
    
    <link name="head_y_link">
        <collision>
            <origin rpy="0 0 0" xyz="0 0 0"/>
            <geometry>
                <box size="0.07 0.1 0.1"/>
            </geometry>
        </collision>
        <visual>
            <origin rpy="0 0 0" xyz="0 0 0"/>
            <geometry>
                <mesh filename="package://thormang3_description/meshes/robotis_head_y_link.stl" scale="0.001 0.001 0.001"/>
            </geometry>
            <material name="grey"/>
        </visual>
        <inertial>
            <origin rpy="0 0 0" xyz="0.0 0.0 0.0"/>
            <mass value="1.0"/>
            <inertia ixx="1.0" ixy="0.0" ixz="0.0" iyy="1.0" iyz="0.0" izz="1.0"/>
        </inertial>
    </link>
    
    <joint name="head_p" type="revolute">
        <axis xyz="0 1 0" />    
        <origin xyz="0.0 -0.045 0.039" rpy="0 0 0"/>
        <parent link="head_y_link"/>
        <child link="head_p_link"/>
        <limit effort="1000" lower="-1.570796327" upper="1.570796327" velocity="6.5"/>
        <dynamics damping="0.1" friction="0.0"/>
    </joint>
    
    <transmission name="head_p_tran">
        <type>transmission_interface/SimpleTransmission</type>
        <joint name="head_p">
            <hardwareInterface>EffortJointInterface</hardwareInterface>
        </joint>
        <actuator name="head_p_motor">
            <hardwareInterface>EffortJointInterface</hardwareInterface>
            <mechanicalReduction>1</mechanicalReduction>
        </actuator>
    </transmission>
    
    <link name="head_p_link">
        <collision>
            <origin rpy="0 0 0" xyz="0.0 0.0 0.0"/>
            <geometry>
                <box size="0.07 0.01 0.01"/>
            </geometry>
        </collision>
        <visual>
            <origin rpy="0 0 0" xyz="0 0 0"/>
            <geometry>
                <mesh filename="package://sam_description/meshes/H42-20-S300-R.stl" scale="0.001 0.001 0.001"/>
            </geometry>
            <material name="grey"/>
        </visual>
        <inertial>
            <origin rpy="0 0 0" xyz="0.0 0.0 0.0"/>
            <mass value="1.0"/>
            <inertia ixx="1.0" ixy="0.0" ixz="0.0" iyy="1.0" iyz="0.0" izz="1.0"/>
        </inertial>
    </link>
    
    <joint name="head_r" type="revolute">
        <axis xyz="0 0 1"/>
        <origin rpy="0 1.5707 0" xyz="0.0 0.045 0.039"/>
        <parent link="head_p_link"/>
        <child link="head_r_link"/>
        <limit effort="1000" lower="-1.570796327" upper="1.570796327" velocity="6.5"/>
        <dynamics damping="0.1" friction="0.0"/>
    </joint>
    
    <transmission name="head_r_tran">
        <type>transmission_interface/SimpleTransmission</type>
        <joint name="head_r">
            <hardwareInterface>EffortJointInterface</hardwareInterface>
        </joint>
        <actuator name="head_r_motor">
            <hardwareInterface>EffortJointInterface</hardwareInterface>
            <mechanicalReduction>1</mechanicalReduction>
        </actuator>
    </transmission>
    
    <link name="head_r_link">
        <collision>
            <origin rpy="0 0 0" xyz="0.0 0.0 -0.045"/>
            <geometry>
                <box size="0.04 0.04 0.09"/>
            </geometry>
        </collision>
        <visual>
            <origin rpy="0 0 0" xyz="0 0 0"/>
            <geometry>
                <mesh filename="package://sam_description/meshes/H42-20-S300-R.stl" scale="0.001 0.001 0.001"/>
            </geometry>
            <material name="grey"/>
        </visual>
        <inertial>
            <origin rpy="0 0 0" xyz="0.0 0.0 0.0"/>
            <mass value="1.0"/>
            <inertia ixx="1.0" ixy="0.0" ixz="0.0" iyy="1.0" iyz="0.0" izz="1.0"/>
        </inertial>
    </link>
    
    <klampt>
        <noselfcollision group1="l_arm_sh_p1_link l_arm_sh_r_link l_arm_sh_p2_link l_arm_el_y_link l_arm_wr_r_link l_arm_wr_y_link"
                         group2="l_arm_sh_r_link l_arm_sh_p2_link l_arm_el_y_link l_arm_wr_r_link l_arm_wr_y_link"/>
        <noselfcollision group1="r_arm_sh_p1_link r_arm_sh_r_link r_arm_sh_p2_link r_arm_el_y_link r_arm_wr_r_link r_arm_wr_y_link"
                         group2="r_arm_sh_r_link r_arm_sh_p2_link r_arm_el_y_link r_arm_wr_r_link r_arm_wr_y_link"/>
        <noselfcollision group1="l_arm_sh_p1_link l_arm_sh_r_link l_arm_sh_p2_link l_arm_el_y_link"
                         group2="chest_link"/>
        <noselfcollision group1="r_arm_sh_p1_link r_arm_sh_r_link r_arm_sh_p2_link r_arm_el_y_link"
                         group2="chest_link"/>
        <noselfcollision group1="l_arm_sh_p1_link l_arm_sh_r_link l_arm_sh_p2_link"
                         group2="pelvis_link"/>
        <noselfcollision group1="r_arm_sh_p1_link r_arm_sh_r_link r_arm_sh_p2_link"
                         group2="pelvis_link"/>
        <noselfcollision group1="l_leg_hip_y_link l_leg_hip_r_link l_leg_hip_p_link l_leg_kn_p_link l_leg_an_p_link l_leg_an_r_link"
                         group2="l_leg_hip_r_link l_leg_hip_p_link l_leg_kn_p_link l_leg_an_p_link l_leg_an_r_link"/>
        <noselfcollision group1="r_leg_hip_y_link r_leg_hip_r_link r_leg_hip_p_link r_leg_kn_p_link r_leg_an_p_link r_leg_an_r_link"
                         group2="r_leg_hip_r_link r_leg_hip_p_link r_leg_kn_p_link r_leg_an_p_link r_leg_an_r_link"/>
    </klampt>
    
</robot>
