<?xml version="1.0" ?>
<robot name="coman" xmlns:xacro="http://ros.org/wiki/xacro">
    <material name="grey">
        <color rgba="0.5 0.5 0.5 1"/>
    </material>
    <material name="dark_grey">
        <color rgba="0.3 0.3 0.3 1"/>
    </material>
    <material name="red">
        <color rgba="1.0 0.0 0.0 1"/>
    </material>
    <material name="hand_color">
        <color rgba="0.2 0.2 0.2 1"/>
    </material>
    
    <link name="world">
    </link>
    <link name="base_link">
    </link>
    <link name="root_link">
    </link>
    
    <joint name="world_fixed" type="fixed">
        <origin xyz="0 0 0" rpy="0 0 0"/>
        <parent link="world"/>
        <child link="base_link"/>
    </joint>
    
    <joint name="root_base" type="fixed">
        <origin xyz="0 0 0.515" rpy="0 0 0"/>
        <parent link="base_link"/>
        <child link="root_link"/>
    </joint>
    
    <link name="Waist">
        <inertial>
            <origin rpy="0.0 0.0 0.0" xyz="-0.026391145 -5.8216364E-4 0.052632312"/>
            <mass value="1.8008695"/>
            <inertia ixx="0.0051032982" ixy="-5.7170981E-5" ixz="0.0016920543" iyy="0.006241636" iyz="1.7225949E-5" izz="0.0024517762"/>
        </inertial>
        <visual>
            <origin rpy="0 0 3.14159265359" xyz="0 0 -0.52"/>
            <material name="dark_grey"/>
            <geometry name="Waist_visual">
                <mesh filename="package://coman_urdf/meshes/Waist.STL" scale="0.03937 0.03937 0.03937"/>
            </geometry>
        </visual>
        <collision>
            <origin rpy="0 0 3.14159265359" xyz="0 0 -0.52"/>
            <geometry name="Waist_collision">
                <mesh filename="package://coman_urdf/meshes/simple/Waist.STL" scale="0.03937 0.03937 0.03937"/>
            </geometry>
        </collision>
    </link>
    
    <joint name="base_joint" type="fixed">
        <origin rpy="0 0 0" xyz="0 0 0"/>
        <parent link="root_link"/>
        <child link="Waist"/>        
    </joint>
    
    <link name="DWL">
        <inertial>
            <origin rpy="0 0 0" xyz="4.2999707E-4 -0.0097650317 0.033011157"/>
            <mass value="0.54588774"/>
            <inertia ixx="9.7126578E-4" ixy="-7.2101244E-7" ixz="1.1440119E-6" iyy="7.4686706E-4" iyz="-1.7450917E-4" izz="6.2196235E-4"/>
        </inertial>
        <visual>
            <origin rpy="0 0 3.14159265359" xyz="-0.020281504 0 -0.63912053"/>
            <material name="dark_grey"/>
            <geometry name="DWL_visual">
                <mesh filename="package://coman_urdf/meshes/Torso1.STL" scale="0.03937 0.03937 0.03937"/>
            </geometry>
        </visual>
        <collision>
            <origin rpy="0 0 3.14159265359" xyz="-0.020281504 0 -0.63912053"/>
            <geometry name="DWL_collision">
                <mesh filename="package://coman_urdf/meshes/simple/Torso1.STL" scale="0.03937 0.03937 0.03937"/>
            </geometry>
        </collision>
    </link>
    <link name="DWS">
        <inertial>
            <origin rpy="0 0 0" xyz="-0.0021273416 0.0033575235 -0.0010076896"/>
            <mass value="0.75398402"/>
            <inertia ixx="3.4093348E-4" ixy="-6.2120042E-6" ixz="-1.3863473E-6" iyy="3.9581916E-4" iyz="1.443019E-6" izz="3.7449753E-4"/>
        </inertial>
        <visual>
            <origin rpy="0 0 3.14159265359" xyz="-0.020281504 0 -0.63912053"/>
            <material name="dark_grey"/>
            <geometry name="DWS_visual">
                <mesh filename="package://coman_urdf/meshes/Torso2.STL" scale="0.03937 0.03937 0.03937"/>
            </geometry>
        </visual>
        <collision>
            <origin rpy="0 0 3.14159265359" xyz="-0.020281504 0 -0.63912053"/>
            <geometry name="DWS_collision">
                <mesh filename="package://coman_urdf/meshes/simple/Torso2.STL" scale="0.03937 0.03937 0.03937"/>
            </geometry>
        </collision>
    </link>
    <link name="DWYTorso">
        <inertial>
            <origin rpy="0 0 0" xyz="-0.0358501 1.8286043E-5 0.117557148"/>
            <mass value="6.3617175"/>
            <inertia ixx="0.034089342" ixy="-9.8308572E-6" ixz="-7.5649290E-4" iyy="0.030117357" iyz="6.2443771E-6" izz="0.025296582"/>
        </inertial>
        <visual>
            <origin rpy="0 0 3.14159265359" xyz="-0.020281504 0.0 -0.68662053"/>
            <material name="red"/>
            <geometry name="DWYTorso_visual">
                <mesh filename="package://coman_urdf/meshes/Torso3.STL" scale="0.03937 0.03937 0.03937"/>
            </geometry>
        </visual>
        <collision>
            <origin rpy="0 0 3.14159265359" xyz="-0.020281504 0.0 -0.68662053"/>
            <geometry name="DWYTorso_collision">
                <mesh filename="package://coman_urdf/meshes/simple/Torso3.STL" scale="0.03937 0.03937 0.03937"/>
            </geometry>
        </collision>
    </link>
    
    <joint name="WaistLat" type="revolute">
        <parent link="Waist"/>
        <child link="DWL"/>
        <origin rpy="0 0 0" xyz="0.020281504 0 0.11912053"/>
        <axis xyz="0.93969262078 0 0.34202014332"/>
        <limit effort="50" lower="-0.5236/2" upper="0.5235/2" velocity="4.0"/>
        <dynamics damping="3.0" friction="0"/>
    </joint>
    <joint name="WaistSag" type="revolute">
        <parent link="DWL"/>
        <child link="DWS"/>
        <origin rpy="0 0 0" xyz="0 0 0"/>
        <axis xyz="0 1 0"/>
        <limit effort="50" lower="-0.3491" upper="0.8727" velocity="4.0"/>
        <dynamics damping="3.0" friction="0"/>
    </joint>
    <joint name="WaistYaw" type="revolute">
        <parent link="DWS"/>
        <child link="DWYTorso"/>
        <origin rpy="0 0 0" xyz="0 0 0.04749999"/>
        <axis xyz="0 0 1"/>
        <limit effort="50" lower="-1.3963/2" upper="1.3962/2" velocity="4.0"/>
        <dynamics damping="3.0" friction="0"/>
    </joint>
    
    <link name="l_toe"/>
    <link name="r_toe"/>
    <link name="RHipMot">
        <inertial>
            <origin rpy="0 0 0" xyz="-3.269678E-4 -0.023587321 -2.6496509E-4"/>
            <mass value="0.89258227"/>
            <inertia ixx="4.7672294E-4" ixy="-3.9936567E-6" ixz="-2.4802574E-6" iyy="5.458038E-4" iyz="-3.3389575E-6" izz="5.126859E-4"/>
        </inertial>
        <visual>
            <origin rpy="0 0 3.14159265359" xyz="0.0 0.023 -0.52"/>
            <material name="dark_grey"/>
            <geometry name="RHipMot_visual">
                <mesh filename="package://coman_urdf/meshes/Leg0.STL" scale="0.03937 0.03937 0.03937"/>
            </geometry>
        </visual>
        <collision>
            <origin rpy="0 0 3.14159265359" xyz="0.0 0.023 -0.52"/>
            <geometry name="RHipMot_collision">
                <mesh filename="package://coman_urdf/meshes/simple/Leg0.STL" scale="0.03937 0.03937 0.03937"/>
            </geometry>
        </collision>
    </link>
    <link name="RThighUpLeg">
        <inertial>
            <origin rpy="0 0 0" xyz="0.0012591632 -0.016896372 -0.058903336"/>
            <mass value="1.0246101"/>
            <inertia ixx="9.165719E-4" ixy="-1.4449904E-6" ixz="-1.6685011E-5" iyy="0.00104849584" iyz="2.5492874E-5" izz="6.8637197E-4"/>
        </inertial>
        <visual>
            <origin rpy="0 0 3.14159265359" xyz="0.0 0.0726 -0.52"/>
            <material name="dark_grey"/>
            <geometry name="RThighUpLeg_visual">
                <mesh filename="package://coman_urdf/meshes/Leg1.STL" scale="0.03937 0.03937 0.03937"/>
            </geometry>
        </visual>
        <collision>
            <origin rpy="0 0 3.14159265359" xyz="0.0 0.0726 -0.52"/>
            <geometry name="RThighUpLeg_collision">
                <mesh filename="package://coman_urdf/meshes/simple/Leg1.STL" scale="0.03937 0.03937 0.03937"/>
            </geometry>
        </collision>
    </link>
    <link name="RThighLowLeg">
        <inertial>
            <origin rpy="0 0 0" xyz="9.8720058E-4 6.7037262E-4 -0.075716843"/>
            <mass value="1.7001134"/>
            <inertia ixx="0.0038979546" ixy="1.7802399E-6" ixz="2.6403262E-5" iyy="0.0039360845" iyz="4.522711E-5" izz="9.0218711E-4"/>
        </inertial>
        <visual>
            <origin rpy="0 0 3.14159265359" xyz="0.0 0.0726 -0.4176"/>
            <material name="dark_grey"/>
            <geometry name="RThighLowLeg_visual">
                <mesh filename="package://coman_urdf/meshes/Leg2.STL" scale="0.03937 0.03937 0.03937"/>
            </geometry>
        </visual>
        <collision>
            <origin rpy="0 0 3.14159265359" xyz="0.0 0.0726 -0.4176"/>
            <geometry name="RThighLowLeg_collision">
                <mesh filename="package://coman_urdf/meshes/simple/Leg2.STL" scale="0.03937 0.03937 0.03937"/>
            </geometry>
        </collision>
    </link>
    <link name="RLowLeg">
        <inertial>
            <origin rpy="0 0 0" xyz="0.0024612666 -0.0053099614 -0.08598948"/>
            <mass value="1.4098179"/>
            <inertia ixx="0.0040604004" ixy="1.1227206E-5" ixz="1.2260973E-5" iyy="0.004005652855" iyz="5.1899176E-4" izz="0.0012414054"/>
        </inertial>
        <visual>
            <origin rpy="0 0 3.14159265359" xyz="0.0 0.0726 -0.2942"/>
            <material name="dark_grey"/>
            <geometry name="RLowLeg_visual">
                <mesh filename="package://coman_urdf/meshes/Leg3.STL" scale="0.03937 0.03937 0.03937"/>
            </geometry>
        </visual>
        <collision>
            <origin rpy="0 0 3.14159265359" xyz="0.0 0.0726 -0.2942"/>
            <geometry name="RLowLeg_collision">
                <mesh filename="package://coman_urdf/meshes/simple/Leg3.STL" scale="0.03937 0.03937 0.03937"/>
            </geometry>
        </collision>
    </link>
    <link name="RFootmot">
        <inertial>
            <origin rpy="0 0 0" xyz="8.8067281E-4 -9.2224881E-4 2.3038476E-4"/>
            <mass value="0.72992131"/>
            <inertia ixx="3.2034425E-4" ixy="7.6346303E-6" ixz="2.5430158E-7" iyy="3.6584358E-4" iyz="-3.6889276E-6" izz="3.6065156E-4"/>
        </inertial>
        <visual>
            <origin rpy="0 0 3.14159265359" xyz="0.0 0.0726 -0.0932"/>
            <material name="dark_grey"/>
            <geometry name="RFootmot_visual">
                <mesh filename="package://coman_urdf/meshes/Leg4.STL" scale="0.03937 0.03937 0.03937"/>
            </geometry>
        </visual>
        <collision>
            <origin rpy="0 0 3.14159265359" xyz="0.0 0.0726 -0.0932"/>
            <geometry name="RFootmot_collision">
                <mesh filename="package://coman_urdf/meshes/simple/Leg4.STL" scale="0.03937 0.03937 0.03937"/>
            </geometry>
        </collision>
    </link>
    <link name="RFoot">
        <inertial>
            <origin rpy="0 0 0" xyz="0.00969210464 -0.0090460227 -0.043062308"/>
            <mass value="0.66646684"/>
            <inertia ixx="0.0012944808" ixy="-9.2387693E-5" ixz="2.0080105E-4" iyy="0.0015851846" iyz="2.7599327E-4" izz="0.0013326766"/>
        </inertial>
        <visual>
            <origin rpy="0 0 0" xyz="0.03 0 -0.07"/>
            <geometry>
                <box size="0.2 0.1 0.04"/>
            </geometry>
            <material name="dark_gray"/>
        </visual>
        <collision>
            <origin rpy="0 0 0" xyz="0.03 0 -0.07"/>
            <geometry>
                <box size="0.2 0.1 0.04"/>
            </geometry>
        </collision>
    </link>
    <link name="LHipMot">
        <inertial>
            <origin rpy="0 0 0" xyz="-3.269678E-4 0.023587321 -2.6496509E-4"/>
            <mass value="0.89258227"/>
            <inertia ixx="4.7672294E-4" ixy="3.9936567E-6" ixz="-2.4802574E-6" iyy="5.458038E-4" iyz="3.3389575E-6" izz="5.126859E-4"/>
        </inertial>
        <visual>
            <origin rpy="0 0 3.14159265359" xyz="0.0 -0.023 -0.52"/>
            <material name="dark_grey"/>
            <geometry name="RHipMot_visual">
                <mesh filename="package://coman_urdf/meshes/Leg0.STL" scale="0.03937 -0.03937 0.03937"/>
            </geometry>
        </visual>
        <collision>
            <origin rpy="0 0 3.14159265359" xyz="0.0 -0.023 -0.52"/>
            <geometry name="RHipMot_collision">
                <mesh filename="package://coman_urdf/meshes/simple/Leg0.STL" scale="0.03937 -0.03937 0.03937"/>
            </geometry>
        </collision>
    </link>
    <link name="LThighUpLeg">
        <inertial>
            <origin rpy="0 0 0" xyz="0.0012591632 0.016896372 -0.058903336"/>
            <mass value="1.0246101"/>
            <inertia ixx="9.165719E-4" ixy="1.4449904E-6" ixz="-1.6685011E-5" iyy="0.00104849584" iyz="-2.5492874E-5" izz="6.8637197E-4"/>
        </inertial>
        <visual>
            <origin rpy="0 0 3.14159265359" xyz="0.0 -0.0726 -0.52"/>
            <material name="dark_grey"/>
            <geometry name="LThighUpLeg_visual">
                <mesh filename="package://coman_urdf/meshes/Leg1.STL" scale="0.03937 -0.03937 0.03937"/>
            </geometry>
        </visual>
        <collision>
            <origin rpy="0 0 3.14159265359" xyz="0.0 -0.0726 -0.52"/>
            <geometry name="LThighUpLeg_collision">
                <mesh filename="package://coman_urdf/meshes/simple/Leg1.STL" scale="0.03937 -0.03937 0.03937"/>
            </geometry>
        </collision>
    </link>
    <link name="LThighLowLeg">
        <inertial>
            <origin rpy="0 0 0" xyz="9.8720058E-4 -6.7037262E-4 -0.075716843"/>
            <mass value="1.7001134"/>
            <inertia ixx="0.0038979546" ixy="-1.7802399E-6" ixz="2.6403262E-5" iyy="0.0039360845" iyz="-4.5227110E-5" izz="9.0218711E-4"/>
        </inertial>
        <visual>
            <origin rpy="0 0 3.14159265359" xyz="0.0 -0.0726 -0.4176"/>
            <material name="dark_grey"/>
            <geometry name="LThighLowLeg_visual">
                <mesh filename="package://coman_urdf/meshes/Leg2.STL" scale="0.03937 -0.03937 0.03937"/>
            </geometry>
        </visual>
        <collision>
            <origin rpy="0 0 3.14159265359" xyz="0.0 -0.0726 -0.4176"/>
            <geometry name="LThighLowLeg_collision">
                <mesh filename="package://coman_urdf/meshes/simple/Leg2.STL" scale="0.03937 -0.03937 0.03937"/>
            </geometry>
        </collision>
    </link>
    <link name="LLowLeg">
        <inertial>
            <origin rpy="0 0 0" xyz="0.0024612666 0.0053099614 -0.085989484"/>
            <mass value="1.4098179"/>
            <inertia ixx="0.0040604004" ixy="-1.1227206E-5" ixz="1.2260973E-5" iyy="0.004005652855" iyz="-5.1899176E-4" izz="0.0012414054"/>
        </inertial>
        <visual>
            <origin rpy="0 0 3.14159265359" xyz="0.0 -0.0726 -0.2942"/>
            <material name="dark_grey"/>
            <geometry name="LLowLeg_visual">
                <mesh filename="package://coman_urdf/meshes/Leg3.STL" scale="0.03937 -0.03937 0.03937"/>
            </geometry>
        </visual>
        <collision>
            <origin rpy="0 0 3.14159265359" xyz="0.0 -0.0726 -0.2942"/>
            <geometry name="LLowLeg_collision">
                <mesh filename="package://coman_urdf/meshes/simple/Leg3.STL" scale="0.03937 -0.03937 0.03937"/>
            </geometry>
        </collision>
    </link>
    <link name="LFootmot">
        <inertial>
            <origin rpy="0 0 0" xyz="8.8067281E-4 9.2224881E-4 2.3038476E-4"/>
            <mass value="0.72992131"/>
            <inertia ixx="3.2034425E-4" ixy="-7.6346303E-6" ixz="2.5430158E-7" iyy="3.6584358E-4" iyz="3.6889276E-6" izz="3.6065156E-4"/>
        </inertial>
        <visual>
            <origin rpy="0 0 3.14159265359" xyz="0.0 -0.0726 -0.0932"/>
            <material name="dark_grey"/>
            <geometry name="LFootmot_visual">
                <mesh filename="package://coman_urdf/meshes/Leg4.STL" scale="0.03937 -0.03937 0.03937"/>
            </geometry>
        </visual>
        <collision>
            <origin rpy="0 0 3.14159265359" xyz="0.0 -0.0726 -0.0932"/>
            <geometry name="LFootmot_collision">
                <mesh filename="package://coman_urdf/meshes/simple/Leg4.STL" scale="0.03937 -0.03937 0.03937"/>
            </geometry>
        </collision>
    </link>
    <link name="LFoot">
        <inertial>
            <origin rpy="0 0 0" xyz="0.0096921046 0.0090460227 -0.043062308"/>
            <mass value="0.66646684"/>
            <inertia ixx="0.0012944808" ixy="9.2387693E-5" ixz="2.0080105E-4" iyy="0.0015851846" iyz="-2.7599327E-4" izz="0.0013326766"/>
        </inertial>
        <visual>
            <origin rpy="0 0 0" xyz="0.03 0 -0.07"/>
            <geometry>
                <box size="0.2 0.1 0.04"/>
            </geometry>
            <material name="dark_gray"/>
        </visual>
        <collision>
            <origin rpy="0 0 0" xyz="0.03 0 -0.07"/>
            <geometry>
                <box size="0.2 0.1 0.04"/>
            </geometry>
        </collision>
    </link>
    <joint name="RHipSag" type="revolute">
        <parent link="Waist"/>
        <child link="RHipMot"/>
        <origin rpy="0 0 0" xyz="0.0 -0.023 0.0"/>
        <axis xyz="0 1 0"/>
        <limit effort="50" lower="-1.9199" upper="0.7854" velocity="4.0"/>
        <dynamics damping="3.0" friction="0"/>
    </joint>
    <joint name="RHipLat" type="revolute">
        <parent link="RHipMot"/>
        <child link="RThighUpLeg"/>
        <origin rpy="0 0 0" xyz="0.0 -0.0496 0.0"/>
        <axis xyz="1 0 0"/>
        <limit effort="50" lower="-1.0472" upper="0.4363" velocity="4.0"/>
        <dynamics damping="3.0" friction="0"/>
    </joint>
    <joint name="RHipYaw" type="revolute">
        <parent link="RThighUpLeg"/>
        <child link="RThighLowLeg"/>
        <origin rpy="0 0 0" xyz="0.0 0.0 -0.1024"/>
        <axis xyz="0 0 1"/>
        <limit effort="50" lower="-0.8727" upper="0.8727" velocity="4.0"/>
        <dynamics damping="3.0" friction="0"/>
    </joint>
    <joint name="RKneeSag" type="revolute">
        <parent link="RThighLowLeg"/>
        <child link="RLowLeg"/>
        <origin rpy="0 0 0" xyz="0.0 0.0 -0.1234"/>
        <axis xyz="0 1 0"/>
        <limit effort="50" lower="-0.1745" upper="1.9199" velocity="4.0"/>
        <dynamics damping="3.0" friction="0"/>
    </joint>
    <joint name="RAnkLat" type="revolute">
        <parent link="RLowLeg"/>
        <child link="RFootmot"/>
        <origin rpy="0 0 0" xyz="0.0 0.0 -0.201"/>
        <axis xyz="1 0 0"/>
        <limit effort="50" lower="-0.6109" upper="0.6109" velocity="4.0"/>
        <dynamics damping="3.0" friction="0"/>
    </joint>
    <joint name="RAnkSag" type="revolute">
        <parent link="RFootmot"/>
        <child link="RFoot"/>
        <origin rpy="0 0 0" xyz="0.0 0.0 0.0"/>
        <axis xyz="0 1 0"/>
        <limit effort="50" lower="-1.2217" upper="1.2217" velocity="4.0"/>
        <dynamics damping="3.0" friction="0"/>
    </joint>
    <joint name="LHipSag" type="revolute">
        <parent link="Waist"/>
        <child link="LHipMot"/>
        <origin rpy="0 0 0" xyz="0.0 0.023 0.0"/>
        <axis xyz="0 1 0"/>
        <limit effort="50" lower="-1.9199" upper="0.7854" velocity="4.0"/>
        <dynamics damping="3.0" friction="0"/>
    </joint>
    <joint name="LHipLat" type="revolute">
        <parent link="LHipMot"/>
        <child link="LThighUpLeg"/>
        <origin rpy="0 0 0" xyz="0.0 0.0496 0.0"/>
        <axis xyz="1 0 0"/>
        <limit effort="50" lower="-0.4363" upper="1.0472" velocity="4.0"/>
        <dynamics damping="3.0" friction="0"/>
    </joint>
    <joint name="LHipYaw" type="revolute">
        <parent link="LThighUpLeg"/>
        <child link="LThighLowLeg"/>
        <origin rpy="0 0 0" xyz="0.0 0.0 -0.1024"/>
        <axis xyz="0 0 1"/>
        <limit effort="50" lower="-0.8727" upper="0.8727" velocity="4.0"/>
        <dynamics damping="3.0" friction="0"/>
    </joint>
    <joint name="LKneeSag" type="revolute">
        <parent link="LThighLowLeg"/>
        <child link="LLowLeg"/>
        <origin rpy="0 0 0" xyz="0.0 0.0 -0.1234"/>
        <axis xyz="0 1 0"/>
        <limit effort="50" lower="-0.1745" upper="1.9199" velocity="4.0"/>
        <dynamics damping="3.0" friction="0"/>
    </joint>
    <joint name="LAnkLat" type="revolute">
        <parent link="LLowLeg"/>
        <child link="LFootmot"/>
        <origin rpy="0 0 0" xyz="0.0 0.0 -0.201"/>
        <axis xyz="1 0 0"/>
        <limit effort="50" lower="-0.6109" upper="0.6109" velocity="4.0"/>
        <dynamics damping="3.0" friction="0"/>
    </joint>
    <joint name="LAnkSag" type="revolute">
        <parent link="LFootmot"/>
        <child link="LFoot"/>
        <origin rpy="0 0 0" xyz="0.0 0.0 0.0"/>
        <axis xyz="0 1 0"/>
        <limit effort="50" lower="-1.2217" upper="1.2217" velocity="4.0"/>
        <dynamics damping="3.0" friction="0"/>
    </joint>
    
    <link name="RShp">
        <inertial>
            <origin rpy="0 0 0" xyz="0.0099500565 -0.038682024 1.6446924E-4"/>
            <mass value="0.56782202"/>
            <inertia ixx="7.8337456E-4" ixy="1.9035768E-4" ixz="-3.0037676E-6" iyy="6.3399921E-4" iyz="4.3840774E-6" izz="0.001008054"/>
        </inertial>
        <visual>
            <origin rpy="0 0 3.14159265359" xyz="-0.005305 0.0825 -0.844329"/>
            <material name="dark_grey"/>
            <geometry name="RShp_visual">
                <mesh filename="package://coman_urdf/meshes/Arm0.STL" scale="0.03937 0.03937 0.03937"/>
            </geometry>
        </visual>
        <collision>
            <origin rpy="0 0 3.14159265359" xyz="-0.005305 0.0825 -0.844329"/>
            <geometry name="RShp_collision">
                <mesh filename="package://coman_urdf/meshes/simple/Arm0.STL" scale="0.03937 0.03937 0.03937"/>
            </geometry>
        </collision>
    </link>
    <link name="RShr">
        <inertial>
            <origin rpy="0 0 0" xyz="-0.0038936743 2.2022151E-6 -0.0048616005"/>
            <mass value="0.77683752"/>
            <inertia ixx="4.5812904E-4" ixy="-2.4111086E-7" ixz="9.2521185E-6" iyy="4.3089204E-4" iyz="-4.7216950E-7" izz="3.4174855E-4"/>
        </inertial>
        <visual>
            <origin rpy="0 0 3.14159265359" xyz="-0.005305 0.1558 -0.844329"/>
            <material name="dark_grey"/>
            <geometry name="RShr_visual">
                <mesh filename="package://coman_urdf/meshes/Arm1.STL" scale="0.03937 0.03937 0.03937"/>
            </geometry>
        </visual>
        <collision>
            <origin rpy="0 0 3.14159265359" xyz="-0.005305 0.1558 -0.844329"/>
            <geometry name="RShr_collision">
                <mesh filename="package://coman_urdf/meshes/simple/Arm1.STL" scale="0.03937 0.03937 0.03937"/>
            </geometry>
        </collision>
    </link>
    <link name="RShy">
        <inertial>
            <origin rpy="0 0 0" xyz="0.0022714213 -0.0071091517 -0.057455221"/>
            <mass value="1.0462304"/>
            <inertia ixx="0.0030934574" ixy="6.6702837E-5" ixz="3.0222291E-4" iyy="0.0029181573" iyz="-5.2663661E-4" izz="8.0830389E-4"/>
        </inertial>
        <visual>
            <origin rpy="0 0 3.14159265359" xyz="-0.005305 0.1558 -0.79952053"/>
            <material name="dark_grey"/>
            <geometry name="RShy_visual">
                <mesh filename="package://coman_urdf/meshes/Arm2.STL" scale="0.03937 0.03937 0.03937"/>
            </geometry>
        </visual>
        <collision>
            <origin rpy="0 0 3.14159265359" xyz="-0.005305 0.1558 -0.79952053"/>
            <geometry name="RShy_collision">
                <mesh filename="package://coman_urdf/meshes/simple/Arm2.STL" scale="0.03937 0.03937 0.03937"/>
            </geometry>
        </collision>
    </link>
    <link name="RElb">
        <inertial>
            <origin rpy="0 0 0" xyz="-6.5553403E-4 -9.3464748E-4 -9.3101289E-4"/>
            <mass value="0.63306933"/>
            <inertia ixx="2.2599075E-4" ixy="-2.6376470E-7" ixz="-9.8007285E-6" iyy="2.7781302E-4" iyz="-2.0435288E-6" izz="2.1878992E-4"/>
        </inertial>
        <visual>
            <origin rpy="-1.570796326795 1.570796326795 0" xyz="0 0 0"/>
            <material name="dark_grey"/>
            <geometry name="RElb_visual">
                <mesh filename="package://coman_urdf/meshes/Elbow.STL" scale="1.0 1.0 1.0"/>
            </geometry>
        </visual>
        <collision>
            <origin rpy="-1.570796326795 1.570796326795 0" xyz="0 0 0"/>
            <geometry name="RElb_collision">
                <mesh filename="package://coman_urdf/meshes/simple/Elbow.STL" scale="1.0 1.0 1.0"/>
            </geometry>
        </collision>
    </link>
    <link name="LShp">
        <inertial>
            <origin rpy="0 0 0" xyz="0.0099500565 0.038682024 1.6446924E-4"/>
            <mass value="0.56782202"/>
            <inertia ixx="7.8337456E-4" ixy="-1.9035768E-4" ixz="-3.0037676E-6" iyy="6.3399921E-4" iyz="-4.3840774E-6" izz="0.001008054"/>
        </inertial>
        <visual>
            <origin rpy="0 0 3.14159265359" xyz="-0.005305 -0.0825 -0.844329"/>
            <material name="dark_grey"/>
            <geometry name="LShp_visual">
                <mesh filename="package://coman_urdf/meshes/Arm0.STL" scale="0.03937 -0.03937 0.03937"/>
            </geometry>
        </visual>
        <collision>
            <origin rpy="0 0 3.14159265359" xyz="-0.005305 -0.0825 -0.844329"/>
            <geometry name="LShp_collision">
                <mesh filename="package://coman_urdf/meshes/simple/Arm0.STL" scale="0.03937 -0.03937 0.03937"/>
            </geometry>
        </collision>
    </link>
    <link name="LShr">
        <inertial>
            <origin rpy="0 0 0" xyz="-0.0038936743 -2.2022151E-6 -0.0048616005"/>
            <mass value="0.77683752"/>
            <inertia ixx="4.5812904E-4" ixy="2.4111086E-7" ixz="9.2521185E-6" iyy="4.3089204E-4" iyz="4.721695E-7" izz="3.4174855E-4"/>
        </inertial>
        <visual>
            <origin rpy="0 0 3.14159265359" xyz="-0.005305 -0.1558 -0.844329"/>
            <material name="dark_grey"/>
            <geometry name="LShr_visual">
                <mesh filename="package://coman_urdf/meshes/Arm1.STL" scale="0.03937 -0.03937 0.03937"/>
            </geometry>
        </visual>
        <collision>
            <origin rpy="0 0 3.14159265359" xyz="-0.005305 -0.1558 -0.844329"/>
            <geometry name="LShr_collision">
                <mesh filename="package://coman_urdf/meshes/simple/Arm1.STL" scale="0.03937 -0.03937 0.03937"/>
            </geometry>
        </collision>
    </link>
    <link name="LShy">
        <inertial>
            <origin rpy="0 0 0" xyz="0.0022714213 0.0071091517 -0.057455221"/>
            <mass value="1.0462304"/>
            <inertia ixx="0.0030934574" ixy="-6.6702837E-5" ixz="3.0222291E-4" iyy="0.0029181573" iyz="5.2663661E-4" izz="8.0830389E-4"/>
        </inertial>
        <visual>
            <origin rpy="0 0 3.14159265359" xyz="-0.005305 -0.1558 -0.79952053"/>
            <material name="dark_grey"/>
            <geometry name="LShy_visual">
                <mesh filename="package://coman_urdf/meshes/Arm2.STL" scale="0.03937 -0.03937 0.03937"/>
            </geometry>
        </visual>
        <collision>
            <origin rpy="0 0 3.14159265359" xyz="-0.005305 -0.1558 -0.79952053"/>
            <geometry name="LShy_collision">
                <mesh filename="package://coman_urdf/meshes/simple/Arm2.STL" scale="0.03937 -0.03937 0.03937"/>
            </geometry>
        </collision>
    </link>
    <link name="LElb">
        <inertial>
            <origin rpy="0 0 0" xyz="-6.5553403E-4 9.3464748E-4 -9.3101289E-4"/>
            <mass value="0.63306933"/>
            <inertia ixx="2.2599075E-4" ixy="2.6376470E-7" ixz="-9.8007285E-6" iyy="2.7781302E-4" iyz="2.0435288E-6" izz="2.1878992E-4"/>
        </inertial>
        <visual>
            <origin rpy="-1.570796326795 1.570796326795 0" xyz="0 0 0"/>
            <material name="dark_grey"/>
            <geometry name="LElb_visual">
                <mesh filename="package://coman_urdf/meshes/Elbow.STL" scale="1.0 1.0 1.0"/>
            </geometry>
        </visual>
        <collision>
            <origin rpy="-1.570796326795 1.570796326795 0" xyz="0 0 0"/>
            <geometry name="LElb_collision">
                <mesh filename="package://coman_urdf/meshes/simple/Elbow.STL" scale="1.0 1.0 1.0"/>
            </geometry>
        </collision>
    </link>
    <joint name="RShSag" type="revolute">
        <parent link="DWYTorso"/>
        <child link="RShp"/>
        <origin rpy="0 0 0" xyz="-0.014976503999999998 -0.0825 0.15770847"/>
        <axis xyz="0 1 0"/>
        <limit effort="50" lower="-3.4034" upper="1.6581" velocity="4.0"/>
        <dynamics damping="3.0" friction="0"/>
    </joint>
    <joint name="RShLat" type="revolute">
        <parent link="RShp"/>
        <child link="RShr"/>
        <origin rpy="-1.5708 0 0" xyz="0.0 -0.07329999999999999 0.0"/>
        <axis xyz="1 0 0"/>
        <limit effort="50" lower="-1.5708" upper="1.3963" velocity="4.0"/>
        <dynamics damping="3.0" friction="0"/>
    </joint>
    <joint name="RShYaw" type="revolute">
        <parent link="RShr"/>
        <child link="RShy"/>
        <origin rpy="0 0 0" xyz="0.0 0.0 -0.04480846999999999"/>
        <axis xyz="0 0 1"/>
        <limit effort="50" lower="-1.5708" upper="1.5708" velocity="4.0"/>
        <dynamics damping="3.0" friction="0"/>
    </joint>
    <joint name="RElbj" type="revolute">
        <parent link="RShy"/>
        <child link="RElb"/>
        <origin rpy="0 0 0" xyz="0.015 0.0 -0.13519152999999998"/>
        <axis xyz="0 1 0"/>
        <limit effort="50" lower="-2.3562" upper="0.0" velocity="4.0"/>
        <dynamics damping="3.0" friction="0"/>
    </joint>
    <joint name="LShSag" type="revolute">
        <parent link="DWYTorso"/>
        <child link="LShp"/>
        <origin rpy="0 0 0" xyz="-0.014976503999999998 0.0825 0.15770847"/>
        <axis xyz="0 1 0"/>
        <limit effort="50" lower="-3.4034" upper="1.6581" velocity="4.0"/>
        <dynamics damping="3.0" friction="0"/>
    </joint>
    <joint name="LShLat" type="revolute">
        <parent link="LShp"/>
        <child link="LShr"/>
        <origin rpy="1.5708 0 0" xyz="0.0 0.07329999999999999 0.0"/>
        <axis xyz="1 0 0"/>
        <limit effort="50" lower="-1.3963" upper="1.5708" velocity="4.0"/>
        <dynamics damping="3.0" friction="0"/>
    </joint>
    <joint name="LShYaw" type="revolute">
        <parent link="LShr"/>
        <child link="LShy"/>
        <origin rpy="0 0 0" xyz="0.0 0.0 -0.04480846999999999"/>
        <axis xyz="0 0 1"/>
        <limit effort="50" lower="-1.5708" upper="1.5708" velocity="4.0"/>
        <dynamics damping="3.0" friction="0"/>
    </joint>
    <joint name="LElbj" type="revolute">
        <parent link="LShy"/>
        <child link="LElb"/>
        <origin rpy="0 0 0" xyz="0.015 0.0 -0.13519152999999998"/>
        <axis xyz="0 1 0"/>
        <limit effort="50" lower="-2.3562" upper="0.0" velocity="4.0"/>
        <dynamics damping="3.0" friction="0"/>
    </joint>
    <link name="LForearm">
        <inertial>
            <origin rpy="0 0 0" xyz="0 0 -0.0282"/>
            <mass value="0.93351655"/>
            <inertia ixx="0.001" ixy="0.0" ixz="0.0" iyy="0.001" iyz="0.0" izz="0.001"/>
        </inertial>
        <visual>
            <origin rpy="3.14159265359 0 1.570796326795" xyz="0 0 0.0718"/>
            <material name="dark_grey"/>
            <geometry name="LForearm_visual">
                <mesh filename="package://coman_urdf/meshes/Forearm0.STL" scale="0.1 0.1 0.1"/>
            </geometry>
        </visual>
        <collision>
            <origin rpy="0 3.14159265359 1.570796326795" xyz="0 0 0.0718"/>
            <geometry name="LForearm_collision">
                <mesh filename="package://coman_urdf/meshes/simple/Forearm0.STL" scale="1.0 1.0 1.0"/>
            </geometry>
        </collision>
    </link>
    <link name="LWrMot2">
        <inertial>
            <origin rpy="0 0 0" xyz="0 0 0"/>
            <mass value="0.26070556"/>
            <inertia ixx="0.000132" ixy="0" ixz="0" iyy="0.000132" iyz="0" izz="5.213E-5"/>
        </inertial>
        <visual>
            <origin rpy="0 1.570796326795 3.14159265359" xyz="0.025 0 0"/>
            <material name="grey"/>
            <geometry name="LWrMot2_visual">
                <mesh filename="package://coman_urdf/meshes/Forearm1.STL" scale="0.001 0.001 0.001"/>
            </geometry>
        </visual>
        <collision>
            <origin rpy="0 1.570796326795 3.14159265359" xyz="0.025 0 0"/>
            <geometry name="LWrMot2_collision">
                <mesh filename="package://coman_urdf/meshes/simple/Forearm1.STL" scale="0.001 0.001 0.001"/>
            </geometry>
        </collision>
    </link>
    <link name="LWrMot3">
        <inertial>
            <origin rpy="0 0 0" xyz="0 0 0"/>
            <mass value="0.054007518"/>
            <inertia ixx="2.16E-5" ixy="0" ixz="0" iyy="2.16E-5" iyz="0" izz="2.16E-5"/>
        </inertial>
        <visual>
            <origin rpy="0 3.14159265359 1.570796326795" xyz="0.025 -0.012 -0.02"/>
            <material name="grey"/>
            <geometry name="LWrMot3_visual">
                <mesh filename="package://coman_urdf/meshes/Forearm2.STL" scale="0.001 0.001 0.001"/>
            </geometry>
        </visual>
        <collision>
            <origin rpy="0 3.14159265359 1.570796326795" xyz="0.025 -0.012 -0.02"/>
            <geometry name="LWrMot3_collision">
                <mesh filename="package://coman_urdf/meshes/simple/Forearm2.STL" scale="0.001 0.001 0.001"/>
            </geometry>
        </collision>
    </link>
    <link name="RForearm">
        <inertial>
            <origin rpy="0 0 0" xyz="0 0 -0.0282"/>
            <mass value="0.93351655"/>
            <inertia ixx="0.001" ixy="0.0" ixz="0.0" iyy="0.001" iyz="0.0" izz="0.001"/>
        </inertial>
        <visual>
            <origin rpy="3.14159265359 0 1.570796326795" xyz="0 0 0.0718"/>
            <material name="dark_grey"/>
            <geometry name="RForearm_visual">
                <mesh filename="package://coman_urdf/meshes/Forearm0.STL" scale="0.1 0.1 0.1"/>
            </geometry>
        </visual>
        <collision>
            <origin rpy="0 3.14159265359 1.570796326795" xyz="0 0 0.0718"/>
            <geometry name="RForearm_collision">
                <mesh filename="package://coman_urdf/meshes/simple/Forearm0.STL" scale="1.0 1.0 1.0"/>
            </geometry>
        </collision>
    </link>
    <link name="RWrMot2">
        <inertial>
            <origin rpy="0 0 0" xyz="0 0 0"/>
            <mass value="0.26070556"/>
            <inertia ixx="0.000132" ixy="0" ixz="0" iyy="0.000132" iyz="0" izz="5.213E-5"/>
        </inertial>
        <visual>
            <origin rpy="0 1.570796326795 3.14159265359" xyz="0.025 0 0"/>
            <material name="grey"/>
            <geometry name="RWrMot2_visual">
                <mesh filename="package://coman_urdf/meshes/Forearm1.STL" scale="0.001 0.001 0.001"/>
            </geometry>
        </visual>
        <collision>
            <origin rpy="0 1.570796326795 3.14159265359" xyz="0.025 0 0"/>
            <geometry name="RWrMot2_collision">
                <mesh filename="package://coman_urdf/meshes/simple/Forearm1.STL" scale="0.001 0.001 0.001"/>
            </geometry>
        </collision>
    </link>
    <link name="RWrMot3">
        <inertial>
            <origin rpy="0 0 0" xyz="0 0 0"/>
            <mass value="0.054007518"/>
            <inertia ixx="2.16E-5" ixy="0" ixz="0" iyy="2.16E-5" iyz="0" izz="2.16E-5"/>
        </inertial>
        <visual>
            <origin rpy="0 3.14159265359 1.570796326795" xyz="0.025 -0.012 -0.02"/>
            <material name="grey"/>
            <geometry name="RWrMot3_visual">
                <mesh filename="package://coman_urdf/meshes/Forearm2.STL" scale="0.001 0.001 0.001"/>
            </geometry>
        </visual>
        <collision>
            <origin rpy="0 3.14159265359 1.570796326795" xyz="0.025 -0.012 -0.02"/>
            <geometry name="RWrMot3_collision">
                <mesh filename="package://coman_urdf/meshes/simple/Forearm2.STL" scale="0.001 0.001 0.001"/>
            </geometry>
        </collision>
    </link>
    <joint name="LForearmPlate" type="revolute">
        <parent link="LElb"/>
        <child link="LForearm"/>
        <origin rpy="0 0 0" xyz="-0.015 0.0 -0.1078"/>
        <axis xyz="0 0 1"/>
        <limit effort="5" lower="-1.5708" upper="1.5708" velocity="4.0"/>
        <dynamics damping="0.03" friction="0"/>
    </joint>
    <joint name="LWrj1" type="revolute">
        <parent link="LForearm"/>
        <child link="LWrMot2"/>
        <origin rpy="0 0 0" xyz="0 0 -0.08688"/>
        <axis xyz="0 1 0"/>
        <limit effort="5" lower="-0.524" upper="0.524" velocity="4.0"/>
        <dynamics damping="0.03" friction="0"/>
    </joint>
    <joint name="LWrj2" type="revolute">
        <parent link="LWrMot2"/>
        <child link="LWrMot3"/>
        <origin rpy="0 0 0" xyz="0 0 0.0"/>
        <axis xyz="1 0 0"/>
        <limit effort="5" lower="-0.785375" upper="1.395" velocity="4.0"/>
        <dynamics damping="0.03" friction="0"/>
    </joint>
    <joint name="RForearmPlate" type="revolute">
        <parent link="RElb"/>
        <child link="RForearm"/>
        <origin rpy="0 0 0" xyz="-0.015 0.0 -0.1078"/>
        <axis xyz="0 0 1"/>
        <limit effort="5" lower="-1.5708" upper="1.5708" velocity="4.0"/>
        <dynamics damping="0.03" friction="0"/>
    </joint>
    <joint name="RWrj1" type="revolute">
        <parent link="RForearm"/>
        <child link="RWrMot2"/>
        <origin rpy="0 0 0" xyz="0 0 -0.08688"/>
        <axis xyz="0 1 0"/>
        <limit effort="5" lower="-0.524" upper="0.524" velocity="4.0"/>
        <dynamics damping="0.03" friction="0"/>
    </joint>
    <joint name="RWrj2" type="revolute">
        <parent link="RWrMot2"/>
        <child link="RWrMot3"/>
        <origin rpy="0 0 0" xyz="0 0 0.0"/>
        <axis xyz="1 0 0"/>
        <limit effort="5" lower="-1.395" upper="0.785375" velocity="4.0"/>
        <dynamics damping="0.03" friction="0"/>
    </joint>
    <link name="l_leg_ft"/>
    <link name="r_leg_ft"/>
    <joint name="l_leg_ft_joint" type="fixed">
        <parent link="LFoot"/>
        <child link="l_leg_ft"/>
        <origin rpy="0 0 0" xyz="0 0 -0.065"/>
    </joint>
    <joint name="r_leg_ft_joint" type="fixed">
        <parent link="RFoot"/>
        <child link="r_leg_ft"/>
        <origin rpy="0 0 0" xyz="0 0 -0.065"/>
    </joint>
    <link name="RSoftHand">
        <inertial>
            <origin rpy="0 0 0" xyz="0 0 0"/>
            <mass value="0.3"/>
            <inertia ixx="0.001" ixy="0" ixz="0" iyy="0.001" iyz="0" izz="0.001"/>
        </inertial>
        <visual>
            <origin rpy="-1.5707963268 0 3.14159265359" xyz="0.007 0.01 -0.04"/>
            <material name="hand_color"/>
            <geometry name="RSoftHand_visual">
                <mesh filename="package://coman_urdf/meshes/SoftHandOpen.STL" scale="0.1 0.1 0.1"/>
            </geometry>
        </visual>
        <collision>
            <origin rpy="0 0 3.14159265359" xyz="0 0.01 -0.04"/>
            <geometry name="RSoftHand_collision">
                <mesh filename="package://coman_urdf/meshes/simple/SoftHandOpen.STL" scale="1E-3 1E-3 1E-3"/>
            </geometry>
        </collision>
    </link>
    <link name="LSoftHand">
        <inertial>
            <origin rpy="0 0 0" xyz="0 0 0"/>
            <mass value="0.3"/>
            <inertia ixx="0.001" ixy="0" ixz="0" iyy="0.001" iyz="0" izz="0.001"/>
        </inertial>
        <visual>
            <origin rpy="-1.5707963268 0 0" xyz="0.007 -0.01 -0.04"/>
            <material name="hand_color"/>
            <geometry name="LSoftHand_visual">
                <mesh filename="package://coman_urdf/meshes/SoftHandOpen.STL" scale="-0.1 0.1 0.1"/>
            </geometry>
        </visual>
        <collision>
            <origin rpy="0 0 0" xyz="0.007 -0.01 -0.04"/>
            <geometry name="LSoftHand_collision">
                <mesh filename="package://coman_urdf/meshes/simple/SoftHandOpen.STL" scale="-1E-3 1E-3 1E-3"/>
            </geometry>
        </collision>
    </link>
    <joint name="r_handj" type="fixed">
        <parent link="RWrMot3"/>
        <child link="RSoftHand"/>
        <origin rpy="0 0 0" xyz="0 0 -0.07"/>
    </joint>
    <joint name="l_handj" type="fixed">
        <parent link="LWrMot3"/>
        <child link="LSoftHand"/>
        <origin rpy="0 0 0" xyz="0 0 -0.07"/>
    </joint>
    
</robot>

