<?xml version='1.0'?>

<robot name="panda" xmlns:xacro="http://www.ros.org/wiki/xacro">

    <link name="world">
    </link>
    <link name="base_link">
    </link>
    
    <joint name="world_fixed" type="fixed">
        <origin xyz="0 0 0" rpy="0 0 0"/>
        <parent link="world"/>
        <child link="base_link"/>
    </joint>
    
    <joint name="root_base" type="fixed">
        <origin xyz="0 0 0.0" rpy="0 0 0"/>
        <parent link="base_link"/>
        <child link="link0"/>
    </joint>
    
    <link name="link0">
        <visual>
            <geometry>
                <mesh filename="package://franka_description/meshes/visual/panda_link0.stl"/>
            </geometry>
        </visual>
        <collision>
            <geometry>
                <mesh filename="package://franka_description/meshes/collision/panda_link0.stl"/>
            </geometry>
        </collision>
    </link>
    <link name="link1">
        <visual>
            <geometry>
                <mesh filename="package://franka_description/meshes/visual/panda_link1.stl"/>
            </geometry>
        </visual>
        <collision>
            <geometry>
                <mesh filename="package://franka_description/meshes/collision/panda_link1.stl"/>
            </geometry>
        </collision>
    </link>
    
    <joint name="joint1" type="revolute">
        <safety_controller k_position="100.0" k_velocity="40.0" soft_lower_limit="-2.8973" soft_upper_limit="2.8973"/>
        <origin rpy="0 0 0" xyz="0 0 0.333"/>
        <parent link="link0"/>
        <child link="link1"/>
        <axis xyz="0 0 1"/>
        <limit effort="87" lower="-2.9671" upper="2.9671" velocity="2.3925"/>
    </joint>
    
    <link name="link2">
        <visual>
            <geometry>
                <mesh filename="package://franka_description/meshes/visual/panda_link2.stl"/>
            </geometry>
        </visual>
        <collision>
            <geometry>
                <mesh filename="package://franka_description/meshes/collision/panda_link2.stl"/>
            </geometry>
        </collision>
    </link>
    <joint name="joint2" type="revolute">
        <safety_controller k_position="100.0" k_velocity="40.0" soft_lower_limit="-1.7628" soft_upper_limit="1.7628"/>
        <origin rpy="-1.570796325 0 0" xyz="0 0 0"/>
        <parent link="link1"/>
        <child link="link2"/>
        <axis xyz="0 0 1"/>
        <limit effort="87" lower="-1.8326" upper="1.8326" velocity="2.3925"/>
    </joint>
    <link name="link3">
        <visual>
            <geometry>
                <mesh filename="package://franka_description/meshes/visual/panda_link3.stl"/>
            </geometry>
        </visual>
        <collision>
            <geometry>
                <mesh filename="package://franka_description/meshes/collision/panda_link3.stl"/>
            </geometry>
        </collision>
    </link>
    
    <joint name="joint3" type="revolute">
        <safety_controller k_position="100.0" k_velocity="40.0" soft_lower_limit="-2.8973" soft_upper_limit="2.8973"/>
        <origin rpy="1.570796325 0 0" xyz="0 -0.316 0"/>
        <parent link="link2"/>
        <child link="link3"/>
        <axis xyz="0 0 1"/>
        <limit effort="87" lower="-2.9671" upper="2.9671" velocity="2.3925"/>
    </joint>
    
    <link name="link4">
        <visual>
            <geometry>
                <mesh filename="package://franka_description/meshes/visual/panda_link4.stl"/>
            </geometry>
        </visual>
        <collision>
            <geometry>
                <mesh filename="package://franka_description/meshes/collision/panda_link4.stl"/>
            </geometry>
        </collision>
    </link>
    
    <joint name="joint4" type="revolute">
        <safety_controller k_position="100.0" k_velocity="40.0" soft_lower_limit="-3.0718" soft_upper_limit="0.0175"/>
        <origin rpy="1.570796325 0 0" xyz="0.0825 0 0"/>
        <parent link="link3"/>
        <child link="link4"/>
        <axis xyz="0 0 1"/>
        <limit effort="87" lower="-3.1416" upper="0.0873" velocity="2.3925"/>
    </joint>
    <link name="link5">
        <visual>
            <geometry>
                <mesh filename="package://franka_description/meshes/visual/panda_link5.stl"/>
            </geometry>
        </visual>
        <collision>
            <geometry>
                <mesh filename="package://franka_description/meshes/collision/panda_link5.stl"/>
            </geometry>
        </collision>
    </link>
    <joint name="joint5" type="revolute">
        <safety_controller k_position="100.0" k_velocity="40.0" soft_lower_limit="-2.8973" soft_upper_limit="2.8973"/>
        <origin rpy="-1.570796325 0 0" xyz="-0.0825 0.384 0"/>
        <parent link="link4"/>
        <child link="link5"/>
        <axis xyz="0 0 1"/>
        <limit effort="12" lower="-2.9671" upper="2.9671" velocity="2.8710"/>
    </joint>
    <link name="link6">
        <visual>
            <geometry>
                <mesh filename="package://franka_description/meshes/visual/panda_link6.stl"/>
            </geometry>
        </visual>
        <collision>
            <geometry>
                <mesh filename="package://franka_description/meshes/collision/panda_link6.stl"/>
            </geometry>
        </collision>
    </link>
    <joint name="joint6" type="revolute">
        <safety_controller k_position="100.0" k_velocity="40.0" soft_lower_limit="-0.0175" soft_upper_limit="3.7525"/>
        <origin rpy="1.570796325 0 0" xyz="0 0 0"/>
        <parent link="link5"/>
        <child link="link6"/>
        <axis xyz="0 0 1"/>
        <limit effort="12" lower="-0.0873" upper="3.8223" velocity="2.8710"/>
    </joint>
    <link name="link7">
        <visual>
            <geometry>
                <mesh filename="package://franka_description/meshes/visual/panda_link7.stl"/>
            </geometry>
        </visual>
        <collision>
            <geometry>
                <mesh filename="package://franka_description/meshes/collision/panda_link7.stl"/>
            </geometry>
        </collision>
    </link>
    <joint name="joint7" type="revolute">
        <safety_controller k_position="100.0" k_velocity="40.0" soft_lower_limit="-2.8973" soft_upper_limit="2.8973"/>
        <origin rpy="1.570796325 0 0" xyz="0.088 0 0"/>
        <parent link="link6"/>
        <child link="link7"/>
        <axis xyz="0 0 1"/>
        <limit effort="12" lower="-2.9671" upper="2.9671" velocity="2.8710"/>
    </joint>
    <joint name="hand" type="fixed">
        <origin rpy="0 0 0" xyz="0 0 0.107"/>
        <parent link="link7"/>
        <child link="link8"/>
        <axis xyz="0 0 1"/>
    </joint>
    <link name="link8">
    </link>
</robot>
